<?xml version="1.0"?>
<robot xmlns:xacro="http://www.ros.org/wiki/xacro" name="my_robot">

    <!--Base Link-->
    <link name="base_link">
    </link>

    <!--Carbody Link -->
    <link name="car_body_link">
        <visual>
          <geometry>
            <mesh filename="package://vehicle_description/meshes/car_body.stl" />
          </geometry>>
        </visual>
        <collision>
            <origin xyz="0.0 0.0 0.294" rpy="0.0 0.0 0.0"/>
            <geometry>
                <box size="1.0 1.2 0.587"/>
            </geometry>
        </collision>
    </link>

    <!--Car Body and Base joint-->
    <joint name="car_body_joint" type="fixed">
        <origin xyz="0 0 0.0" rpy="0.0 0.0 0.0"/>
        <parent link="base_link"/>
        <child link="car_body_link"/>
    </joint>

    <!--Steering Link-->
    <!-- Front Left Steering-->
    <link name="front_left_s_link">
        <inertial>
            <mass value="13.0"/>
            <inertia ixx="0.0" ixy="0.0" ixz="0.0" iyy="0.0" iyz="0.0" izz="0.0"/>
        </inertial>
        <visual>
            <geometry>
                <mesh filename="package://vehicle_description/meshes/steering.stl"/>
            </geometry>
        </visual>
    </link>
    <!-- Front Right Steering-->
    <link name="front_right_s_link">
        <inertial>
            <mass value="13.0"/>
            <inertia ixx="0.0" ixy="0.0" ixz="0.0" iyy="0.0" iyz="0.0" izz="0.0"/>
        </inertial>
        <visual>
            <geometry>
                <mesh filename="package://vehicle_description/meshes/steering.stl"/>
            </geometry>
        </visual>
    </link>
    <!-- Back Left Steering-->
    <link name="back_left_s_link">
        <inertial>
            <mass value="13.0"/>
            <inertia ixx="0.0" ixy="0.0" ixz="0.0" iyy="0.0" iyz="0.0" izz="0.0"/>
        </inertial>
        <visual>
            <geometry>
                <mesh filename="package://vehicle_description/meshes/steering.stl"/>
            </geometry>
        </visual>
    </link>
    <!-- Back Right Steering-->
    <link name="back_right_s_link">
        <inertial>
            <mass value="13.0"/>
            <inertia ixx="0.0" ixy="0.0" ixz="0.0" iyy="0.0" iyz="0.0" izz="0.0"/>
        </inertial>
        <visual>
            <geometry>
                <mesh filename="package://vehicle_description/meshes/steering.stl"/>
            </geometry>
        </visual>
    </link>


    <!--Wheel Link-->
    <!-- Front Left Wheel -->
    <link name="front_left_w_link">
        <inertial>
            <mass value="0.5"/>
            <inertia ixx="0.0" ixy="0.0" ixz="0.0" iyy="0.0" iyz="0.0" izz="0.0"/>
        </inertial>
        <visual>
            <geometry>
                <mesh filename="package://vehicle_description/meshes/wheel.stl" />
            </geometry>
        </visual>
    </link>
    <!--Front Right Wheel-->
    <link name="front_right_w_link">
        <inertial>
            <mass value="0.5"/>
            <inertia ixx="0.0" ixy="0.0" ixz="0.0" iyy="0.0" iyz="0.0" izz="0.0"/>
        </inertial>
        <visual>
            <geometry>
                <mesh filename="package://vehicle_description/meshes/wheel.stl" />
            </geometry>
        </visual>
    </link>
    <!-- Back Left Wheel -->
    <link name="back_left_w_link">
        <inertial>
            <mass value="0.5"/>
            <inertia ixx="0.0" ixy="0.0" ixz="0.0" iyy="0.0" iyz="0.0" izz="0.0"/>
        </inertial>
        <visual>
            <geometry>
                <mesh filename="package://vehicle_description/meshes/wheel.stl" />
            </geometry>
        </visual>
    </link>
    <!--Back Right Wheel-->
    <link name="back_right_w_link">
        <inertial>
            <mass value="0.5"/>
            <inertia ixx="0.0" ixy="0.0" ixz="0.0" iyy="0.0" iyz="0.0" izz="0.0"/>
        </inertial>
        <visual>
            <geometry>
                <mesh filename="package://vehicle_description/meshes/wheel.stl" />
            </geometry>
        </visual>
    </link>

    <!--Steering Joints-->
    <!--Front Left Steering Joint-->
    <joint name="front_left_s_joint" type="revolute">
        <origin xyz="0.278 -0.45 0.0" rpy="0.0 0.0 1.5708"/>
        <parent link="car_body_link"/>
        <child link="front_left_s_link"/>
        <axis xyz="0.0 0.0 1.0"/>
        <limit lower="-1.047" upper="1.047" effort="20.0" velocity="314.16"/>
    </joint>
    <!--Front Right Steering Joint-->
    <joint name="front_right_s_joint" type="revolute">
        <origin xyz="-0.278 -0.45 0.0" rpy="0.0 0.0 1.5708"/>
        <parent link="car_body_link"/>
        <child link="front_right_s_link"/>
        <axis xyz="0.0 0.0 1.0"/>
        <limit lower="-1.047" upper="1.047" effort="20.0" velocity="314.16"/>
    </joint>   
        <!--Back Left Steering Joint-->
    <joint name="back_left_s_joint" type="revolute">
        <origin xyz="0.278 0.45 0.0" rpy="0.0 0.0 -1.5708"/>
        <parent link="car_body_link"/>
        <child link="back_left_s_link"/>
        <axis xyz="0.0 0.0 1.0"/>
        <limit lower="-1.047" upper="1.047" effort="20.0" velocity="314.16"/>
    </joint>
    <!--Front Right Steering Joint-->
    <joint name="back_right_s_joint" type="revolute">
        <origin xyz="-0.278 0.45 0.0" rpy="0.0 0.0 -1.5708"/>
        <parent link="car_body_link"/>
        <child link="back_right_s_link"/>
        <axis xyz="0.0 0.0 1.0"/>
        <limit lower="-1.047" upper="1.047" effort="20.0" velocity="314.16"/>
    </joint>  

    <!--Wheel Rotating Joints-->
    <!--Front Left Wheel Joint-->
    <joint name="front_left_r_joint" type="continuous">
        <parent link="front_left_s_link"/>
        <child link="front_left_w_link"/>
        <axis xyz="0.0 1.0 0.0"/>
        <origin xyz="0 0 0.065"/>
    </joint>
    <!--Front Right Wheel Joint-->
    <joint name="front_right_r_joint" type="continuous">
        <parent link="front_right_s_link"/>
        <child link="front_right_w_link"/>
        <axis xyz="0.0 1.0 0.0"/>
        <origin xyz="0 0 0.065"/>
    </joint>
        <!--Back Left Wheel Joint-->
    <joint name="back_left_r_joint" type="continuous">
        <parent link="back_left_s_link"/>
        <child link="back_left_w_link"/>
        <axis xyz="0.0 1.0 0.0"/>
        <origin xyz="0 0 0.065"/>
    </joint>
    <!--Back Right Wheel Joint-->
    <joint name="back_right_r_joint" type="continuous">
        <parent link="back_right_s_link"/>
        <child link="back_right_w_link"/>
        <axis xyz="0.0 1.0 0.0"/>
        <origin xyz="0 0 0.065"/>
    </joint>

</robot>

